#### Callstack Depth Attack [Deprecado]

##### Descrição

Neste ataque, qualquer chamada (mesmo uma completamente confiável e correta) pode falhar. Isto ocorre porque existe um limite na pilha de chamadas no ambiente de aplicações Ethereum. Chamadas recursivas possuem um limite 1023 itens na pilha de chamadas, e chamadas subsequentes (que incluem por exemplo _send()_) irão falhar.

##### Exemplo

Neste exemplo, a chamada a _send()_ pode falhar se a pilha de chamadas for muito grande, no entanto o restante da função irá funcionar, incluindo a linha que zera a quantia do reembolso do cliente:

```
contract leilao {
    mapping(address => uint) reembolsos;

    // [...]

    function withdrawRefund(address destinatario) {
      uint reembolso = reembolsos[destinatario];
      reembolsos[destinatario] = 0;
      destinatario.send(reembolso);
    }
}
```

##### Detecção

Este ataque está deprecado desde [EIP 150](https://github.com/ethereum/EIPs/issues/150) - todo **GAS** será consumido antes da pilha chegar à chamada 1024.

##### Mitigação

O código revisto abaixo irá eliminar o problema revertendo a ação caso ela não ocorra com sucesso:

```
contract auction {
    mapping(address => uint) refunds;

    // [...]

    function withdrawRefund(address recipient) {
      uint refund = refunds[recipient];
      refunds[recipient] = 0;
      if (!recipient.send(refund)) { throw; } // the transaction will be reverted in case of call depth attack
    }
}
```

##### Fontes

* [Ethereum Wiki](https://github.com/ethereum/wiki/wiki/Safety)
